<?xml version="1.0" encoding="utf-8"?>
<!-- =================================================================================== -->
<!-- |    This document was autogenerated by xacro from torobo.urdf.xacro              | -->
<!-- |    EDITING THIS FILE BY HAND IS NOT RECOMMENDED                                 | -->
<!-- =================================================================================== -->
<robot name="torobo">
  <!-- ros_control plugin -->
  <gazebo>
    <plugin filename="libtorobo_gazebo_ros_control.so" name="torobo_gazebo_ros_control">
      <robotNamespace>/torobo</robotNamespace>
      <robotSimType>torobo_gazebo_ros_control/DefaultRobotHWSim</robotSimType>
      <legacyModeNS>false</legacyModeNS>
    </plugin>
  </gazebo>
  <!-- Link1 -->
  <gazebo reference="arm/link_1">
    <mu1>0.2</mu1>
    <mu2>0.2</mu2>
  </gazebo>
  <!-- Link2 -->
  <gazebo reference="arm/link_2">
    <mu1>0.2</mu1>
    <mu2>0.2</mu2>
  </gazebo>
  <!-- Link3 -->
  <gazebo reference="arm/link_3">
    <mu1>0.2</mu1>
    <mu2>0.2</mu2>
  </gazebo>
  <!-- Link4 -->
  <gazebo reference="arm/link_4">
    <mu1>0.2</mu1>
    <mu2>0.2</mu2>
  </gazebo>
  <!-- Link5 -->
  <gazebo reference="arm/link_5">
    <mu1>0.2</mu1>
    <mu2>0.2</mu2>
  </gazebo>
  <!-- Link6 -->
  <gazebo reference="arm/link_6">
    <mu1>0.2</mu1>
    <mu2>0.2</mu2>
  </gazebo>
  <!-- Link7 -->
  <gazebo reference="arm/link_7">
    <mu1>0.2</mu1>
    <mu2>0.2</mu2>
  </gazebo>
  <!-- =============== Link & Joint =============== -->
  <joint name="arm/root" type="fixed">
    <origin xyz="0 0 0"/>
    <parent link="base"/>
    <child link="arm/link_0"/>
  </joint>
  <link name="arm/link_0">
    <visual>
      <geometry>
        <mesh filename="package://torobo_resources/TRBA-R-003-7/meshes/link0.dae" scale="0.01 0.01 0.01"/>
      </geometry>
      <origin xyz="0 0 0"/>
    </visual>
    <collision>
      <geometry>
        <mesh filename="package://torobo_resources/TRBA-R-003-7/meshes/link0.dae" scale="0.012 0.012 0.012"/>
      </geometry>
      <origin xyz="0 0 0"/>
    </collision>
    <inertial>
      <origin xyz="-0.000436 0.000019 0.041708"/>
      <mass value="2.545036"/>
      <inertia ixx="6.331898e-3" ixy="2.399900e-6" ixz="-3.132040e-5" iyy="6.434612e-3" iyz="1.515900e-6" izz="8.449834e-3"/>
    </inertial>
  </link>
  <joint name="arm/joint_1" type="revolute">
    <parent link="arm/link_0"/>
    <child link="arm/link_1"/>
    <origin rpy="0 0 0" xyz="0 0 0.220"/>
    <axis xyz="0 0 1"/>
    <limit effort="110" lower="-2.96705972839" upper="2.96705972839" velocity="1.74532925199"/>
  </joint>
  <link name="arm/link_1">
    <visual>
      <geometry>
        <mesh filename="package://torobo_resources/TRBA-R-003-7/meshes/link1.dae" scale="0.01 0.01 0.01"/>
      </geometry>
    </visual>
    <collision>
      <geometry>
        <mesh filename="package://torobo_resources/TRBA-R-003-7/meshes/link1.dae" scale="0.012 0.012 0.012"/>
      </geometry>
    </collision>
    <inertial>
      <origin xyz="0.000009 0.004526 -0.062965"/>
      <mass value="4.553552"/>
      <inertia ixx="2.644887e-2" ixy="5.349000e-7" ixz="4.084800e-6" iyy="2.675988e-2" iyz="-8.294709e-4" izz="7.305179e-3"/>
    </inertial>
  </link>
  <joint name="arm/joint_2" type="revolute">
    <parent link="arm/link_1"/>
    <child link="arm/link_2"/>
    <origin rpy="-1.57079632679 0 0" xyz="0 0 0"/>
    <axis xyz="0 0 1"/>
    <limit effort="110" lower="-1.91986217719" upper="1.91986217719" velocity="1.74532925199"/>
  </joint>
  <link name="arm/link_2">
    <visual>
      <geometry>
        <mesh filename="package://torobo_resources/TRBA-R-003-7/meshes/link2.dae" scale="0.01 0.01 0.01"/>
      </geometry>
    </visual>
    <collision>
      <geometry>
        <mesh filename="package://torobo_resources/TRBA-R-003-7/meshes/link2.dae" scale="0.012 0.012 0.012"/>
      </geometry>
    </collision>
    <inertial>
      <origin xyz="0.000000 -0.064474 -0.016924"/>
      <mass value="2.474676"/>
      <inertia ixx="1.163631e-2" ixy="-6.892000e-7" ixz="2.103000e-7" iyy="4.853435e-3" iyz="2.196366e-3" izz="1.202305e-2"/>
    </inertial>
  </link>
  <joint name="arm/joint_3" type="revolute">
    <parent link="arm/link_2"/>
    <child link="arm/link_3"/>
    <origin rpy="1.57079632679 0 0" xyz="0 -0.3 0"/>
    <axis xyz="0 0 1"/>
    <limit effort="70" lower="-2.87979326579" upper="2.87979326579" velocity="2.61799387799"/>
  </joint>
  <link name="arm/link_3">
    <visual>
      <geometry>
        <mesh filename="package://torobo_resources/TRBA-R-003-7/meshes/link3.dae" scale="0.01 0.01 0.01"/>
      </geometry>
    </visual>
    <collision>
      <geometry>
        <mesh filename="package://torobo_resources/TRBA-R-003-7/meshes/link3.dae" scale="0.012 0.012 0.012"/>
      </geometry>
    </collision>
    <inertial>
      <origin xyz="0.000012 0.005769 -0.066866"/>
      <mass value="3.237919"/>
      <inertia ixx="1.911238e-2" ixy="2.978000e-7" ixz="-4.962600e-6" iyy="1.915428e-2" iyz="-7.716287e-4" izz="3.920768e-3"/>
    </inertial>
  </link>
  <joint name="arm/joint_4" type="revolute">
    <parent link="arm/link_3"/>
    <child link="arm/link_4"/>
    <origin rpy="-1.57079632679 0 0" xyz="0 0 0"/>
    <axis xyz="0 0 1"/>
    <limit effort="70" lower="-2.18166156499" upper="2.18166156499" velocity="2.61799387799"/>
  </joint>
  <link name="arm/link_4">
    <visual>
      <geometry>
        <mesh filename="package://torobo_resources/TRBA-R-003-7/meshes/link4.dae" scale="0.01 0.01 0.01"/>
      </geometry>
    </visual>
    <collision>
      <geometry>
        <mesh filename="package://torobo_resources/TRBA-R-003-7/meshes/link4.dae" scale="0.012 0.012 0.012"/>
      </geometry>
    </collision>
    <inertial>
      <origin xyz="0.000006 -0.062765 -0.018379"/>
      <mass value="1.945562"/>
      <inertia ixx="9.626170e-3" ixy="-1.551000e-7" ixz="1.278000e-7" iyy="2.996661e-3" iyz="1.733720e-3" izz="9.870906e-3"/>
    </inertial>
  </link>
  <joint name="arm/joint_5" type="revolute">
    <parent link="arm/link_4"/>
    <child link="arm/link_5"/>
    <origin rpy="1.57079632679 0 0" xyz="0 -0.3 0"/>
    <axis xyz="0 0 1"/>
    <limit effort="30" lower="-2.87979326579" upper="2.87979326579" velocity="2.79252680319"/>
  </joint>
  <link name="arm/link_5">
    <visual>
      <geometry>
        <mesh filename="package://torobo_resources/TRBA-R-003-7/meshes/link5.dae" scale="0.01 0.01 0.01"/>
      </geometry>
    </visual>
    <collision>
      <geometry>
        <mesh filename="package://torobo_resources/TRBA-R-003-7/meshes/link5.dae" scale="0.012 0.012 0.012"/>
      </geometry>
    </collision>
    <inertial>
      <origin xyz="-0.000009 0.010041 -0.094026"/>
      <mass value="1.798056"/>
      <inertia ixx="9.196412e-3" ixy="2.212000e-7" ixz="6.890000e-7" iyy="9.130626e-3" iyz="-1.559966e-3" izz="1.957429e-3"/>
    </inertial>
  </link>
  <joint name="arm/joint_6" type="revolute">
    <parent link="arm/link_5"/>
    <child link="arm/link_6"/>
    <origin rpy="-1.57079632679 0 0" xyz="0 0 0"/>
    <axis xyz="0 0 1"/>
    <limit effort="30" lower="-2.09439510239" upper="2.09439510239" velocity="2.79252680319"/>
  </joint>
  <link name="arm/link_6">
    <visual>
      <geometry>
        <mesh filename="package://torobo_resources/TRBA-R-003-7/meshes/link6.dae" scale="0.01 0.01 0.01"/>
      </geometry>
    </visual>
    <collision>
      <geometry>
        <mesh filename="package://torobo_resources/TRBA-R-003-7/meshes/link6.dae" scale="0.012 0.012 0.012"/>
      </geometry>
    </collision>
    <inertial>
      <origin xyz="0.000002 -0.050748 -0.002319"/>
      <mass value="2.271792"/>
      <inertia ixx="8.528173e-3" ixy="-5.321000e-7" ixz="4.298000e-7" iyy="2.242304e-3" iyz="1.159234e-4" izz="8.444133e-3"/>
    </inertial>
  </link>
  <joint name="arm/joint_7" type="revolute">
    <parent link="arm/link_6"/>
    <child link="arm/link_7"/>
    <origin rpy="1.57079632679 0 0" xyz="0 -0.170 0"/>
    <axis xyz="0 0 1"/>
    <limit effort="15" lower="-2.96705972839" upper="2.96705972839" velocity="4.18879020479"/>
  </joint>
  <link name="arm/link_7">
    <visual>
      <geometry>
        <mesh filename="package://torobo_resources/TRBA-R-003-7/meshes/link7.dae" scale="0.01 0.01 0.01"/>
      </geometry>
    </visual>
    <collision>
      <geometry>
        <mesh filename="package://torobo_resources/TRBA-R-003-7/meshes/link7.dae" scale="0.012 0.012 0.012"/>
      </geometry>
    </collision>
    <inertial>
      <origin xyz="-0.000973 0.000022 -0.017659"/>
      <mass value="0.265534"/>
      <inertia ixx="1.433657e-4" ixy="-5.220000e-8" ixz="5.026000e-7" iyy="1.455343e-4" iyz="-1.360000e-8" izz="2.086642e-4"/>
    </inertial>
  </link>
  <transmission name="arm/joint_1_transmission">
    <type>transmission_interface/SimpleTransmission</type>
    <actuator name="arm/joint_1_motor">
      <mechanicalReduction>1</mechanicalReduction>
      <hardwareInterface>hardware_interface/PositionJointInterface</hardwareInterface>
    </actuator>
    <joint name="arm/joint_1">
      <hardwareInterface>hardware_interface/PositionJointInterface</hardwareInterface>
    </joint>
  </transmission>
  <transmission name="arm/joint_2_transmission">
    <type>transmission_interface/SimpleTransmission</type>
    <actuator name="arm/joint_2_motor">
      <mechanicalReduction>1</mechanicalReduction>
      <hardwareInterface>hardware_interface/PositionJointInterface</hardwareInterface>
    </actuator>
    <joint name="arm/joint_2">
      <hardwareInterface>hardware_interface/PositionJointInterface</hardwareInterface>
    </joint>
  </transmission>
  <transmission name="arm/joint_3_transmission">
    <type>transmission_interface/SimpleTransmission</type>
    <actuator name="arm/joint_3_motor">
      <mechanicalReduction>1</mechanicalReduction>
      <hardwareInterface>hardware_interface/PositionJointInterface</hardwareInterface>
    </actuator>
    <joint name="arm/joint_3">
      <hardwareInterface>hardware_interface/PositionJointInterface</hardwareInterface>
    </joint>
  </transmission>
  <transmission name="arm/joint_4_transmission">
    <type>transmission_interface/SimpleTransmission</type>
    <actuator name="arm/joint_4_motor">
      <mechanicalReduction>1</mechanicalReduction>
      <hardwareInterface>hardware_interface/PositionJointInterface</hardwareInterface>
    </actuator>
    <joint name="arm/joint_4">
      <hardwareInterface>hardware_interface/PositionJointInterface</hardwareInterface>
    </joint>
  </transmission>
  <transmission name="arm/joint_5_transmission">
    <type>transmission_interface/SimpleTransmission</type>
    <actuator name="arm/joint_5_motor">
      <mechanicalReduction>1</mechanicalReduction>
      <hardwareInterface>hardware_interface/PositionJointInterface</hardwareInterface>
    </actuator>
    <joint name="arm/joint_5">
      <hardwareInterface>hardware_interface/PositionJointInterface</hardwareInterface>
    </joint>
  </transmission>
  <transmission name="arm/joint_6_transmission">
    <type>transmission_interface/SimpleTransmission</type>
    <actuator name="arm/joint_6_motor">
      <mechanicalReduction>1</mechanicalReduction>
      <hardwareInterface>hardware_interface/PositionJointInterface</hardwareInterface>
    </actuator>
    <joint name="arm/joint_6">
      <hardwareInterface>hardware_interface/PositionJointInterface</hardwareInterface>
    </joint>
  </transmission>
  <transmission name="arm/joint_7_transmission">
    <type>transmission_interface/SimpleTransmission</type>
    <actuator name="arm/joint_7_motor">
      <mechanicalReduction>1</mechanicalReduction>
      <hardwareInterface>hardware_interface/PositionJointInterface</hardwareInterface>
    </actuator>
    <joint name="arm/joint_7">
      <hardwareInterface>hardware_interface/PositionJointInterface</hardwareInterface>
    </joint>
  </transmission>
  <link name="gripper/gripper_base">
    <visual>
      <geometry>
        <mesh filename="package://torobo_resources/TRBG-L-B-001/meshes/gripper_base.dae" scale="0.01 0.01 0.01"/>
      </geometry>
      <origin rpy="0 0 1.57079632679" xyz="0 0 0"/>
    </visual>
    <collision>
      <geometry>
        <mesh filename="package://torobo_resources/TRBG-L-B-001/meshes/gripper_base.dae" scale="0.012 0.012 0.012"/>
      </geometry>
      <origin rpy="0 0 1.57079632679" xyz="0 0 0"/>
    </collision>
    <inertial>
      <origin rpy="0 0 0" xyz="0 -0.007 0.046"/>
      <mass value="0.76"/>
      <inertia ixx="1.104105e-3" ixy="2.054322e-5" ixz="-5.411983e-6" iyy="7.765804e-4" iyz="3.247528e-5" izz="6.346240e-4"/>
    </inertial>
  </link>
  <joint name="gripper/gripper_base_joint" type="fixed">
    <parent link="arm/link_7"/>
    <child link="gripper/gripper_base"/>
    <origin rpy="0 0 0" xyz="0 0 0"/>
  </joint>
  <link name="gripper/grasping_frame">
    <visual>
      <origin rpy="0 0 0" xyz="0 0 0"/>
      <geometry>
        <box size="0.02 0.02 0.02"/>
      </geometry>
      <material name="clear_color">
        <color rgba="0.5 0.5 0.5 0.1"/>
      </material>
    </visual>
    <!--
    <collision>
      <origin xyz="0 0 0" rpy="0 0 0"/>
      <geometry>
        <box size="0.02 0.02 0.02" />
      </geometry>
    </collision>
    -->
  </link>
  <joint name="gripper/grasping_frame_joint" type="fixed">
    <parent link="gripper/gripper_base"/>
    <child link="gripper/grasping_frame"/>
    <origin rpy="0 0 0" xyz="0 0 0.16"/>
  </joint>
  <link name="gripper/finger_link">
    <visual>
      <origin rpy="0 0 -1.57079632679" xyz="0 0 0"/>
      <geometry>
        <mesh filename="package://torobo_resources/TRBG-L-B-001/meshes/finger.dae" scale="0.01 0.01 0.01"/>
      </geometry>
    </visual>
    <collision>
      <origin rpy="0 0 -1.57079632679" xyz="0 0 0"/>
      <geometry>
        <mesh filename="package://torobo_resources/TRBG-L-B-001/meshes/finger.dae" scale="0.012 0.012 0.012"/>
      </geometry>
    </collision>
    <inertial>
      <origin rpy="0 0 0" xyz="0 0.007 0.046"/>
      <mass value="0.03"/>
      <inertia ixx="0.0004" ixy="0" ixz="0" iyy="0.0004" iyz="0" izz="0.0004"/>
    </inertial>
  </link>
  <link name="gripper/mimic_link">
    <visual>
      <origin rpy="0 0 -1.57079632679" xyz="0 0 0"/>
      <geometry>
        <mesh filename="package://torobo_resources/TRBG-L-B-001/meshes/finger.dae" scale="0.01 0.01 0.01"/>
      </geometry>
    </visual>
    <collision>
      <origin rpy="0 0 -1.57079632679" xyz="0 0 0"/>
      <geometry>
        <mesh filename="package://torobo_resources/TRBG-L-B-001/meshes/finger.dae" scale="0.012 0.012 0.012"/>
      </geometry>
    </collision>
    <inertial>
      <origin rpy="0 0 0" xyz="0 -0.007 0.046"/>
      <mass value="0.03"/>
      <inertia ixx="0.0004" ixy="0" ixz="0" iyy="0.0004" iyz="0" izz="0.0004"/>
    </inertial>
  </link>
  <joint name="gripper/finger_joint" type="prismatic">
    <parent link="gripper/mimic_link"/>
    <child link="gripper/finger_link"/>
    <origin rpy="0 0 3.14159265359" xyz="0 0 0"/>
    <axis xyz="0 1 0"/>
    <limit effort="50" lower="0" upper="0.08" velocity="0.5"/>
  </joint>
  <joint name="gripper/mimic_joint" type="prismatic">
    <parent link="gripper/gripper_base"/>
    <child link="gripper/mimic_link"/>
    <origin rpy="0 0 0" xyz="0 0 0"/>
    <axis xyz="0 1 0"/>
    <limit effort="50" lower="0" upper="0.04" velocity="0.5"/>
    <mimic joint="gripper/finger_joint" multiplier="0.5" offset="0.0"/>
  </joint>
  <transmission name="gripper/finger_joint_transmission">
    <type>transmission_interface/SimpleTransmission</type>
    <actuator name="gripper/finger_joint_motor">
      <mechanicalReduction>1</mechanicalReduction>
      <hardwareInterface>hardware_interface/PositionJointInterface</hardwareInterface>
    </actuator>
    <joint name="gripper/finger_joint">
      <hardwareInterface>hardware_interface/PositionJointInterface</hardwareInterface>
    </joint>
  </transmission>
  <transmission name="gripper/mimic_joint_transmission">
    <type>transmission_interface/SimpleTransmission</type>
    <actuator name="gripper/mimic_joint_motor">
      <mechanicalReduction>1</mechanicalReduction>
      <hardwareInterface>hardware_interface/PositionJointInterface</hardwareInterface>
    </actuator>
    <joint name="gripper/mimic_joint">
      <hardwareInterface>hardware_interface/PositionJointInterface</hardwareInterface>
    </joint>
  </transmission>
  <!-- ros_control plugin -->
  <gazebo>
  </gazebo>
  <!-- grasping_frame -->
  <gazebo reference="gripper/grasping_frame">
    <mu1>0.2</mu1>
    <mu2>0.2</mu2>
  </gazebo>
  <!-- gripper_base -->
  <gazebo reference="gripper/gripper_base">
    <mu1>0.2</mu1>
    <mu2>0.2</mu2>
  </gazebo>
  <!-- right_finger -->
  <gazebo reference="gripper/finger_joint">
    <mu1>0.2</mu1>
    <mu2>0.2</mu2>
  </gazebo>
  <!-- left_finger -->
  <gazebo reference="gripper/mimic_joint">
    <mu1>0.2</mu1>
    <mu2>0.2</mu2>
  </gazebo>
  <!-- =============== Link & Joint =============== -->
  <link name="world"/>
  <joint name="joint_base" type="fixed">
    <origin xyz="0 0 0.785"/>
    <parent link="world"/>
    <child link="base"/>
  </joint>
  <link name="base">
    <visual>
      <origin xyz="0 0 0"/>
      <geometry>
        <cylinder length="0.015" radius="0.09"/>
      </geometry>
      <material name="white">
        <color rgba="1 1 1 1"/>
      </material>
    </visual>
    <visual>
      <origin xyz="0 0 -0.3925"/>
      <geometry>
        <box size="0.10 0.10 0.785"/>
      </geometry>
      <material name="white">
        <color rgba="1 1 1 1"/>
      </material>
    </visual>
    <collision>
      <origin xyz="0 0 0"/>
      <geometry>
        <cylinder length="0.015" radius="0.09"/>
      </geometry>
    </collision>
    <collision>
      <origin xyz="0 0 -0.3925"/>
      <geometry>
        <box size="0.10 0.10 0.785"/>
      </geometry>
    </collision>
    <inertial>
      <origin xyz="0 0 0"/>
      <mass value="1"/>
      <inertia ixx="1" ixy="0" ixz="0" iyy="1" iyz="0" izz="1"/>
    </inertial>
  </link>
</robot>

