<?xml version="1.0" encoding="utf-8"?>
<!-- =================================================================================== -->
<!-- |    This document was autogenerated by xacro from torobo.urdf.xacro              | -->
<!-- |    EDITING THIS FILE BY HAND IS NOT RECOMMENDED                                 | -->
<!-- =================================================================================== -->
<robot name="torobo">
    <link name="base_link">
        <inertial>
            <origin xyz="0 0 0.14" rpy="0 -0 0" />
            <mass value="4" />
            <inertia ixx="0.4" iyy="0.4" izz="0.4" ixy="0" ixz="0" iyz="0" />
        </inertial>
        <visual>
            <origin xyz="0 0 0.01"/>
            <geometry>
                <mesh filename="meshes/link0.obj" scale="0.01 0.01 0.01"/>
            </geometry>
        </visual>
        <!-- <collision>
            <origin xyz="0 0 0" rpy="0 -0 0" />
            <geometry>
                <mesh filename="meshes/base.obj" scale="1 1 1" />
            </geometry>
        </collision> -->
    </link> 
    <!-- =================== Link =================== -->
    <link name="link0">
        <inertial>
            <origin xyz="-0.000436 0.000019 0.041708"/>
            <mass value="2.545036"/>
            <inertia ixx="6.331898e-3" ixy="2.399900e-6" ixz="-3.132040e-5" iyy="6.434612e-3" iyz="1.515900e-6" izz="8.449834e-3"/>
        </inertial>
        <visual>
            <origin xyz="0 0 0.0" rpy="0 -0 0" />
            <geometry>
                <mesh filename="meshes/link1.obj" scale="0.01 0.01 0.01"/>
            </geometry>
        </visual>
        <!--            <collision>
            <origin xyz="0 0 0"/>
            <geometry>
                <mesh filename="meshes/link0.obj" scale="0.012 0.012 0.012"/>
            </geometry>
        </collision> -->
   </link> 


    <link name="link1">
        <inertial>
            <origin xyz="0.000009 0.004526 -0.062965"/>
            <mass value="4.553552"/>
            <inertia ixx="2.644887e-2" ixy="5.349000e-7" ixz="4.084800e-6" iyy="2.675988e-2" iyz="-8.294709e-4" izz="7.305179e-3"/>
        </inertial>
        <visual>
            <origin xyz="0 0 0" rpy="0 0 0" />
            <geometry>
                <mesh filename="meshes/link2.obj" scale="0.01 0.01 0.01"/>
            </geometry>
        </visual>
        <!-- <collision>
            <origin xyz="0 0 0" rpy="0 -0 0" />
            <geometry>
                <mesh filename="meshes/link1.obj" scale="0.012 0.012 0.012"/>
            </geometry>
        </collision> -->
    </link>


    <link name="link2">
        <inertial>
            <origin xyz="0.000000 -0.064474 -0.016924"/>
            <mass value="2.474676"/>
            <inertia ixx="1.163631e-2" ixy="-6.892000e-7" ixz="2.103000e-7" iyy="4.853435e-3" iyz="2.196366e-3" izz="1.202305e-2"/>
        </inertial>
        <visual>
            <origin xyz="0 0 0.0" rpy="0 -0 0" />
            <geometry>
                <mesh filename="meshes/link3.obj" scale="0.01 0.01 0.01"/>
            </geometry>
        </visual>
        <!-- <collision>
            <origin xyz="0 0 0" rpy="0 -0 0" />
            <geometry>
                <mesh filename="meshes/link2.obj" scale="0.012 0.012 0.012"/>
            </geometry>
        </collision> -->
    </link>


    <link name="link3">
        <inertial>
            <origin xyz="0.000012 0.005769 -0.066866"/>
            <mass value="3.237919"/>
            <inertia ixx="1.911238e-2" ixy="2.978000e-7" ixz="-4.962600e-6" iyy="1.915428e-2" iyz="-7.716287e-4" izz="3.920768e-3"/>
        </inertial>
        <visual>
            <origin xyz="0 0 0" rpy="0 0 0" />
            <geometry>
                <mesh filename="meshes/link4.obj" scale="0.01 0.01 0.01"/>
            </geometry>
        </visual>
        <!-- <collision>
            <origin xyz="0 0 0" rpy="0 -0 0" />
            <geometry>
                <mesh filename="meshes/link3.obj" scale="0.012 0.012 0.012"/>
            </geometry>
        </collision> -->
    </link>


    <link name="link4">
        <inertial>
            <origin xyz="0.000006 -0.062765 -0.018379"/>
            <mass value="1.945562"/>
            <inertia ixx="9.626170e-3" ixy="-1.551000e-7" ixz="1.278000e-7" iyy="2.996661e-3" iyz="1.733720e-3" izz="9.870906e-3"/>
        </inertial>
        <visual>
            <origin xyz="0 -0.00 0" rpy="0 -0 0" />
            <geometry>
                <mesh filename="meshes/link5.obj" scale="0.01 0.01 0.01"/>
            </geometry>
        </visual>
        <!-- <collision>
            <origin xyz="0 0 0" rpy="0 -0 0" />
            <geometry>
                <mesh filename="meshes/link4.obj" scale="0.012 0.012 0.012"/>
            </geometry>
        </collision> -->
    </link>


    <link name="link5">
        <inertial>
            <origin xyz="-0.000009 0.010041 -0.094026"/>
            <mass value="1.798056"/>
            <inertia ixx="9.196412e-3" ixy="2.212000e-7" ixz="6.890000e-7" iyy="9.130626e-3" iyz="-1.559966e-3" izz="1.957429e-3"/>
        </inertial>
        <visual>
            <origin xyz="0 0 0" rpy="0 0 0" />
            <geometry>
                <mesh filename="meshes/link6.obj" scale="0.01 0.01 0.01"/>
            </geometry>
        </visual>
        <!-- <collision>
            <origin xyz="0 -0.06 0" rpy="0 -0 0" />
            <geometry>
                <mesh filename="meshes/link5.obj" scale="0.012 0.012 0.012"/>
            </geometry>
        </collision> -->
    </link>


    <link name="link6">
        <inertial>
            <origin xyz="0.000002 -0.050748 -0.002319"/>
            <mass value="2.271792"/>
            <inertia ixx="8.528173e-3" ixy="-5.321000e-7" ixz="4.298000e-7" iyy="2.242304e-3" iyz="1.159234e-4" izz="8.444133e-3"/>
        </inertial>
        <visual>
            <origin xyz="0 0 0.0" rpy="0 -0 0" />
            <geometry>
                <mesh filename="meshes/link7.obj" scale="0.01 0.01 0.01"/>
            </geometry>
        </visual>
        <!-- <collision>
            <origin xyz="0 -0.06 0" rpy="0 -0 0" />
            <geometry>
                <mesh filename="meshes/link6.obj" scale="0.012 0.012 0.012"/>
            </geometry>
        </collision> -->
    </link>
 
    <!-- =================== Joint =================== -->
     <joint name="j0" type="revolute">
        <parent link="base_link" />
        <child link="link0" />
        <origin xyz="0 0 0.220" rpy="0 0 0" />
        <axis xyz="0 0 1"/>
        <limit lower="-2.96705972839" upper="2.96705972839" effort="110" velocity="1.74532925199"/>
    </joint>

    <joint name="j1" type="revolute">
        <parent link="link0"/>
        <child link="link1"/>
        <origin rpy="-1.57079632679 0 0" xyz="0 0 0"/>
        <axis xyz="0 0 1"/>
        <limit effort="110" lower="-1.91986217719" upper="1.91986217719" velocity="1.74532925199"/>
    </joint>
    <joint name="j2" type="revolute">
        <parent link="link1"/>
        <child link="link2"/>
        <origin rpy="1.57079632679 0 0" xyz="0 -0.3 0"/>
        <axis xyz="0 0 1"/>
        <limit effort="70" lower="-2.87979326579" upper="2.87979326579" velocity="2.61799387799"/>
    </joint>

    <joint name="j3" type="revolute">
        <parent link="link2"/>
        <child link="link3"/>
        <origin rpy="-1.57079632679 0 0" xyz="0 0 0"/>
        <axis xyz="0 0 1"/>
        <limit effort="70" lower="-2.18166156499" upper="2.18166156499" velocity="2.61799387799"/>
    </joint>
    <joint name="j4" type="revolute">
        <parent link="link3"/>
        <child link="link4"/>
        <origin rpy="1.57079632679 0 0" xyz="0 -0.3 0"/>
        <axis xyz="0 0 1"/>
        <limit effort="30" lower="-2.87979326579" upper="2.87979326579" velocity="2.79252680319"/>
    </joint>
    <joint name="j5" type="revolute">
        <parent link="link4"/>
        <child link="link5"/>
        <origin rpy="-1.57079632679 0 0" xyz="0 0 0"/>
        <axis xyz="0 0 1"/>
        <limit effort="30" lower="-2.09439510239" upper="2.09439510239" velocity="2.79252680319"/>
    </joint>
    <joint name="j6" type="revolute">
        <parent link="link5"/>
        <child link="link6"/>
        <origin rpy="1.57079632679 0 0" xyz="0 -0.170 0"/>
        <axis xyz="0 0 1"/>
        <limit effort="15" lower="-2.96705972839" upper="2.96705972839" velocity="4.18879020479"/>
    </joint>
</robot>

